[2025-04-17T15:01:58.201+0000] {local_task_job_runner.py:123} INFO - ::group::Pre task execution logs
[2025-04-17T15:01:58.249+0000] {taskinstance.py:2613} INFO - Dependencies all met for dep_context=non-requeueable deps ti=<TaskInstance: full_pipeline.flink_transform scheduled__2025-04-17T14:00:00+00:00 [queued]>
[2025-04-17T15:01:58.262+0000] {taskinstance.py:2613} INFO - Dependencies all met for dep_context=requeueable deps ti=<TaskInstance: full_pipeline.flink_transform scheduled__2025-04-17T14:00:00+00:00 [queued]>
[2025-04-17T15:01:58.262+0000] {taskinstance.py:2866} INFO - Starting attempt 1 of 2
[2025-04-17T15:01:58.277+0000] {taskinstance.py:2889} INFO - Executing <Task(BashOperator): flink_transform> on 2025-04-17 14:00:00+00:00
[2025-04-17T15:01:58.280+0000] {standard_task_runner.py:72} INFO - Started process 8398 to run task
[2025-04-17T15:01:58.283+0000] {standard_task_runner.py:104} INFO - Running: ['airflow', 'tasks', 'run', 'full_pipeline', 'flink_transform', 'scheduled__2025-04-17T14:00:00+00:00', '--job-id', '882', '--raw', '--subdir', 'DAGS_FOLDER/full_pipeline_dag.py', '--cfg-path', '/tmp/tmpe3ku6s_4']
[2025-04-17T15:01:58.285+0000] {standard_task_runner.py:105} INFO - Job 882: Subtask flink_transform
[2025-04-17T15:01:58.431+0000] {task_command.py:467} INFO - Running <TaskInstance: full_pipeline.flink_transform scheduled__2025-04-17T14:00:00+00:00 [running]> on host 772d115850d3
[2025-04-17T15:01:58.712+0000] {taskinstance.py:3132} INFO - Exporting env vars: AIRFLOW_CTX_DAG_OWNER='data_team' AIRFLOW_CTX_DAG_ID='full_pipeline' AIRFLOW_CTX_TASK_ID='flink_transform' AIRFLOW_CTX_EXECUTION_DATE='2025-04-17T14:00:00+00:00' AIRFLOW_CTX_TRY_NUMBER='1' AIRFLOW_CTX_DAG_RUN_ID='scheduled__2025-04-17T14:00:00+00:00'
[2025-04-17T15:01:58.713+0000] {taskinstance.py:731} INFO - ::endgroup::
[2025-04-17T15:01:58.726+0000] {subprocess.py:78} INFO - Tmp dir root location: /tmp
[2025-04-17T15:01:58.727+0000] {subprocess.py:88} INFO - Running command: ['/usr/bin/bash', '-c', 'python /opt/airflow/pipeline/process/flink_stream.py']
[2025-04-17T15:01:58.733+0000] {subprocess.py:99} INFO - Output:
[2025-04-17T15:01:58.865+0000] {subprocess.py:106} INFO - Traceback (most recent call last):
[2025-04-17T15:01:58.866+0000] {subprocess.py:106} INFO -   File "/opt/airflow/pipeline/process/flink_stream.py", line 8, in <module>
[2025-04-17T15:01:58.868+0000] {subprocess.py:106} INFO -     import wget
[2025-04-17T15:01:58.868+0000] {subprocess.py:106} INFO - ModuleNotFoundError: No module named 'wget'
[2025-04-17T15:01:58.872+0000] {subprocess.py:110} INFO - Command exited with return code 1
[2025-04-17T15:01:58.917+0000] {taskinstance.py:3311} ERROR - Task failed with exception
Traceback (most recent call last):
  File "/home/airflow/.local/lib/python3.12/site-packages/airflow/models/taskinstance.py", line 767, in _execute_task
    result = _execute_callable(context=context, **execute_callable_kwargs)
             ^^^^^^^^^^^^^^^^^^^^^^^^^^^^^^^^^^^^^^^^^^^^^^^^^^^^^^^^^^^^^
  File "/home/airflow/.local/lib/python3.12/site-packages/airflow/models/taskinstance.py", line 733, in _execute_callable
    return ExecutionCallableRunner(
           ^^^^^^^^^^^^^^^^^^^^^^^^
  File "/home/airflow/.local/lib/python3.12/site-packages/airflow/utils/operator_helpers.py", line 252, in run
    return self.func(*args, **kwargs)
           ^^^^^^^^^^^^^^^^^^^^^^^^^^
  File "/home/airflow/.local/lib/python3.12/site-packages/airflow/models/baseoperator.py", line 422, in wrapper
    return func(self, *args, **kwargs)
           ^^^^^^^^^^^^^^^^^^^^^^^^^^^
  File "/home/airflow/.local/lib/python3.12/site-packages/airflow/operators/bash.py", line 276, in execute
    raise AirflowException(
airflow.exceptions.AirflowException: Bash command failed. The command returned a non-zero exit code 1.
[2025-04-17T15:01:58.927+0000] {taskinstance.py:1225} INFO - Marking task as UP_FOR_RETRY. dag_id=full_pipeline, task_id=flink_transform, run_id=scheduled__2025-04-17T14:00:00+00:00, execution_date=20250417T140000, start_date=20250417T150158, end_date=20250417T150158
[2025-04-17T15:01:58.952+0000] {taskinstance.py:340} INFO - ::group::Post task execution logs
[2025-04-17T15:01:58.953+0000] {standard_task_runner.py:124} ERROR - Failed to execute job 882 for task flink_transform (Bash command failed. The command returned a non-zero exit code 1.; 8398)
Traceback (most recent call last):
  File "/home/airflow/.local/lib/python3.12/site-packages/airflow/task/task_runner/standard_task_runner.py", line 117, in _start_by_fork
    ret = args.func(args, dag=self.dag)
          ^^^^^^^^^^^^^^^^^^^^^^^^^^^^^
  File "/home/airflow/.local/lib/python3.12/site-packages/airflow/cli/cli_config.py", line 49, in command
    return func(*args, **kwargs)
           ^^^^^^^^^^^^^^^^^^^^^
  File "/home/airflow/.local/lib/python3.12/site-packages/airflow/utils/cli.py", line 116, in wrapper
    return f(*args, **kwargs)
           ^^^^^^^^^^^^^^^^^^
  File "/home/airflow/.local/lib/python3.12/site-packages/airflow/cli/commands/task_command.py", line 483, in task_run
    task_return_code = _run_task_by_selected_method(args, _dag, ti)
                       ^^^^^^^^^^^^^^^^^^^^^^^^^^^^^^^^^^^^^^^^^^^^
  File "/home/airflow/.local/lib/python3.12/site-packages/airflow/cli/commands/task_command.py", line 256, in _run_task_by_selected_method
    return _run_raw_task(args, ti)
           ^^^^^^^^^^^^^^^^^^^^^^^
  File "/home/airflow/.local/lib/python3.12/site-packages/airflow/cli/commands/task_command.py", line 341, in _run_raw_task
    return ti._run_raw_task(
           ^^^^^^^^^^^^^^^^^
  File "/home/airflow/.local/lib/python3.12/site-packages/airflow/utils/session.py", line 97, in wrapper
    return func(*args, session=session, **kwargs)
           ^^^^^^^^^^^^^^^^^^^^^^^^^^^^^^^^^^^^^^
  File "/home/airflow/.local/lib/python3.12/site-packages/airflow/models/taskinstance.py", line 3005, in _run_raw_task
    return _run_raw_task(
           ^^^^^^^^^^^^^^
  File "/home/airflow/.local/lib/python3.12/site-packages/airflow/models/taskinstance.py", line 273, in _run_raw_task
    TaskInstance._execute_task_with_callbacks(
  File "/home/airflow/.local/lib/python3.12/site-packages/airflow/models/taskinstance.py", line 3159, in _execute_task_with_callbacks
    result = self._execute_task(context, task_orig)
             ^^^^^^^^^^^^^^^^^^^^^^^^^^^^^^^^^^^^^^
  File "/home/airflow/.local/lib/python3.12/site-packages/airflow/models/taskinstance.py", line 3183, in _execute_task
    return _execute_task(self, context, task_orig)
           ^^^^^^^^^^^^^^^^^^^^^^^^^^^^^^^^^^^^^^^
  File "/home/airflow/.local/lib/python3.12/site-packages/airflow/models/taskinstance.py", line 767, in _execute_task
    result = _execute_callable(context=context, **execute_callable_kwargs)
             ^^^^^^^^^^^^^^^^^^^^^^^^^^^^^^^^^^^^^^^^^^^^^^^^^^^^^^^^^^^^^
  File "/home/airflow/.local/lib/python3.12/site-packages/airflow/models/taskinstance.py", line 733, in _execute_callable
    return ExecutionCallableRunner(
           ^^^^^^^^^^^^^^^^^^^^^^^^
  File "/home/airflow/.local/lib/python3.12/site-packages/airflow/utils/operator_helpers.py", line 252, in run
    return self.func(*args, **kwargs)
           ^^^^^^^^^^^^^^^^^^^^^^^^^^
  File "/home/airflow/.local/lib/python3.12/site-packages/airflow/models/baseoperator.py", line 422, in wrapper
    return func(self, *args, **kwargs)
           ^^^^^^^^^^^^^^^^^^^^^^^^^^^
  File "/home/airflow/.local/lib/python3.12/site-packages/airflow/operators/bash.py", line 276, in execute
    raise AirflowException(
airflow.exceptions.AirflowException: Bash command failed. The command returned a non-zero exit code 1.
[2025-04-17T15:01:58.979+0000] {local_task_job_runner.py:266} INFO - Task exited with return code 1
[2025-04-17T15:01:59.039+0000] {taskinstance.py:3895} INFO - 0 downstream tasks scheduled from follow-on schedule check
[2025-04-17T15:01:59.042+0000] {local_task_job_runner.py:245} INFO - ::endgroup::
