[2025-04-17T11:38:58.714+0000] {local_task_job_runner.py:123} INFO - ::group::Pre task execution logs
[2025-04-17T11:38:58.783+0000] {taskinstance.py:2613} INFO - Dependencies all met for dep_context=non-requeueable deps ti=<TaskInstance: full_pipeline.extract_weather manual__2025-04-17T11:33:33.134925+00:00 [queued]>
[2025-04-17T11:38:58.805+0000] {taskinstance.py:2613} INFO - Dependencies all met for dep_context=requeueable deps ti=<TaskInstance: full_pipeline.extract_weather manual__2025-04-17T11:33:33.134925+00:00 [queued]>
[2025-04-17T11:38:58.806+0000] {taskinstance.py:2866} INFO - Starting attempt 2 of 2
[2025-04-17T11:38:58.833+0000] {taskinstance.py:2889} INFO - Executing <Task(BashOperator): extract_weather> on 2025-04-17 11:33:33.134925+00:00
[2025-04-17T11:38:58.839+0000] {standard_task_runner.py:72} INFO - Started process 365 to run task
[2025-04-17T11:38:58.843+0000] {standard_task_runner.py:104} INFO - Running: ['airflow', 'tasks', 'run', 'full_pipeline', 'extract_weather', 'manual__2025-04-17T11:33:33.134925+00:00', '--job-id', '823', '--raw', '--subdir', 'DAGS_FOLDER/full_pipeline_dag.py', '--cfg-path', '/tmp/tmpj3d18nj3']
[2025-04-17T11:38:58.846+0000] {standard_task_runner.py:105} INFO - Job 823: Subtask extract_weather
[2025-04-17T11:38:59.047+0000] {task_command.py:467} INFO - Running <TaskInstance: full_pipeline.extract_weather manual__2025-04-17T11:33:33.134925+00:00 [running]> on host 04906466de51
[2025-04-17T11:38:59.362+0000] {taskinstance.py:3132} INFO - Exporting env vars: AIRFLOW_CTX_DAG_OWNER='data_team' AIRFLOW_CTX_DAG_ID='full_pipeline' AIRFLOW_CTX_TASK_ID='extract_weather' AIRFLOW_CTX_EXECUTION_DATE='2025-04-17T11:33:33.134925+00:00' AIRFLOW_CTX_TRY_NUMBER='2' AIRFLOW_CTX_DAG_RUN_ID='manual__2025-04-17T11:33:33.134925+00:00'
[2025-04-17T11:38:59.363+0000] {taskinstance.py:731} INFO - ::endgroup::
[2025-04-17T11:38:59.377+0000] {subprocess.py:78} INFO - Tmp dir root location: /tmp
[2025-04-17T11:38:59.378+0000] {subprocess.py:88} INFO - Running command: ['/usr/bin/bash', '-c', 'python D:\\Course\\EPSI M1 IA\\Cours\\Data pipeline\\MinIO/extract/fetch_weather_stream.py']
[2025-04-17T11:38:59.388+0000] {subprocess.py:99} INFO - Output:
[2025-04-17T11:38:59.416+0000] {subprocess.py:106} INFO - python: can't open file '/tmp/airflowtmp_tlj7kk6/D:CourseEPSI': [Errno 2] No such file or directory
[2025-04-17T11:38:59.418+0000] {subprocess.py:110} INFO - Command exited with return code 2
[2025-04-17T11:38:59.467+0000] {taskinstance.py:3311} ERROR - Task failed with exception
Traceback (most recent call last):
  File "/home/airflow/.local/lib/python3.12/site-packages/airflow/models/taskinstance.py", line 767, in _execute_task
    result = _execute_callable(context=context, **execute_callable_kwargs)
             ^^^^^^^^^^^^^^^^^^^^^^^^^^^^^^^^^^^^^^^^^^^^^^^^^^^^^^^^^^^^^
  File "/home/airflow/.local/lib/python3.12/site-packages/airflow/models/taskinstance.py", line 733, in _execute_callable
    return ExecutionCallableRunner(
           ^^^^^^^^^^^^^^^^^^^^^^^^
  File "/home/airflow/.local/lib/python3.12/site-packages/airflow/utils/operator_helpers.py", line 252, in run
    return self.func(*args, **kwargs)
           ^^^^^^^^^^^^^^^^^^^^^^^^^^
  File "/home/airflow/.local/lib/python3.12/site-packages/airflow/models/baseoperator.py", line 422, in wrapper
    return func(self, *args, **kwargs)
           ^^^^^^^^^^^^^^^^^^^^^^^^^^^
  File "/home/airflow/.local/lib/python3.12/site-packages/airflow/operators/bash.py", line 276, in execute
    raise AirflowException(
airflow.exceptions.AirflowException: Bash command failed. The command returned a non-zero exit code 2.
[2025-04-17T11:38:59.472+0000] {taskinstance.py:1225} INFO - Marking task as FAILED. dag_id=full_pipeline, task_id=extract_weather, run_id=manual__2025-04-17T11:33:33.134925+00:00, execution_date=20250417T113333, start_date=20250417T113858, end_date=20250417T113859
[2025-04-17T11:38:59.492+0000] {taskinstance.py:340} INFO - ::group::Post task execution logs
[2025-04-17T11:38:59.493+0000] {standard_task_runner.py:124} ERROR - Failed to execute job 823 for task extract_weather (Bash command failed. The command returned a non-zero exit code 2.; 365)
Traceback (most recent call last):
  File "/home/airflow/.local/lib/python3.12/site-packages/airflow/task/task_runner/standard_task_runner.py", line 117, in _start_by_fork
    ret = args.func(args, dag=self.dag)
          ^^^^^^^^^^^^^^^^^^^^^^^^^^^^^
  File "/home/airflow/.local/lib/python3.12/site-packages/airflow/cli/cli_config.py", line 49, in command
    return func(*args, **kwargs)
           ^^^^^^^^^^^^^^^^^^^^^
  File "/home/airflow/.local/lib/python3.12/site-packages/airflow/utils/cli.py", line 116, in wrapper
    return f(*args, **kwargs)
           ^^^^^^^^^^^^^^^^^^
  File "/home/airflow/.local/lib/python3.12/site-packages/airflow/cli/commands/task_command.py", line 483, in task_run
    task_return_code = _run_task_by_selected_method(args, _dag, ti)
                       ^^^^^^^^^^^^^^^^^^^^^^^^^^^^^^^^^^^^^^^^^^^^
  File "/home/airflow/.local/lib/python3.12/site-packages/airflow/cli/commands/task_command.py", line 256, in _run_task_by_selected_method
    return _run_raw_task(args, ti)
           ^^^^^^^^^^^^^^^^^^^^^^^
  File "/home/airflow/.local/lib/python3.12/site-packages/airflow/cli/commands/task_command.py", line 341, in _run_raw_task
    return ti._run_raw_task(
           ^^^^^^^^^^^^^^^^^
  File "/home/airflow/.local/lib/python3.12/site-packages/airflow/utils/session.py", line 97, in wrapper
    return func(*args, session=session, **kwargs)
           ^^^^^^^^^^^^^^^^^^^^^^^^^^^^^^^^^^^^^^
  File "/home/airflow/.local/lib/python3.12/site-packages/airflow/models/taskinstance.py", line 3005, in _run_raw_task
    return _run_raw_task(
           ^^^^^^^^^^^^^^
  File "/home/airflow/.local/lib/python3.12/site-packages/airflow/models/taskinstance.py", line 273, in _run_raw_task
    TaskInstance._execute_task_with_callbacks(
  File "/home/airflow/.local/lib/python3.12/site-packages/airflow/models/taskinstance.py", line 3159, in _execute_task_with_callbacks
    result = self._execute_task(context, task_orig)
             ^^^^^^^^^^^^^^^^^^^^^^^^^^^^^^^^^^^^^^
  File "/home/airflow/.local/lib/python3.12/site-packages/airflow/models/taskinstance.py", line 3183, in _execute_task
    return _execute_task(self, context, task_orig)
           ^^^^^^^^^^^^^^^^^^^^^^^^^^^^^^^^^^^^^^^
  File "/home/airflow/.local/lib/python3.12/site-packages/airflow/models/taskinstance.py", line 767, in _execute_task
    result = _execute_callable(context=context, **execute_callable_kwargs)
             ^^^^^^^^^^^^^^^^^^^^^^^^^^^^^^^^^^^^^^^^^^^^^^^^^^^^^^^^^^^^^
  File "/home/airflow/.local/lib/python3.12/site-packages/airflow/models/taskinstance.py", line 733, in _execute_callable
    return ExecutionCallableRunner(
           ^^^^^^^^^^^^^^^^^^^^^^^^
  File "/home/airflow/.local/lib/python3.12/site-packages/airflow/utils/operator_helpers.py", line 252, in run
    return self.func(*args, **kwargs)
           ^^^^^^^^^^^^^^^^^^^^^^^^^^
  File "/home/airflow/.local/lib/python3.12/site-packages/airflow/models/baseoperator.py", line 422, in wrapper
    return func(self, *args, **kwargs)
           ^^^^^^^^^^^^^^^^^^^^^^^^^^^
  File "/home/airflow/.local/lib/python3.12/site-packages/airflow/operators/bash.py", line 276, in execute
    raise AirflowException(
airflow.exceptions.AirflowException: Bash command failed. The command returned a non-zero exit code 2.
[2025-04-17T11:38:59.501+0000] {local_task_job_runner.py:266} INFO - Task exited with return code 1
[2025-04-17T11:38:59.678+0000] {taskinstance.py:3895} INFO - 0 downstream tasks scheduled from follow-on schedule check
[2025-04-17T11:38:59.685+0000] {local_task_job_runner.py:245} INFO - ::endgroup::
