[2025-04-17T14:02:14.282+0000] {local_task_job_runner.py:123} INFO - ::group::Pre task execution logs
[2025-04-17T14:02:14.328+0000] {taskinstance.py:2613} INFO - Dependencies all met for dep_context=non-requeueable deps ti=<TaskInstance: full_pipeline.flink_transform scheduled__2025-04-17T13:00:00+00:00 [queued]>
[2025-04-17T14:02:14.340+0000] {taskinstance.py:2613} INFO - Dependencies all met for dep_context=requeueable deps ti=<TaskInstance: full_pipeline.flink_transform scheduled__2025-04-17T13:00:00+00:00 [queued]>
[2025-04-17T14:02:14.341+0000] {taskinstance.py:2866} INFO - Starting attempt 1 of 2
[2025-04-17T14:02:14.355+0000] {taskinstance.py:2889} INFO - Executing <Task(BashOperator): flink_transform> on 2025-04-17 13:00:00+00:00
[2025-04-17T14:02:14.360+0000] {standard_task_runner.py:72} INFO - Started process 6194 to run task
[2025-04-17T14:02:14.363+0000] {standard_task_runner.py:104} INFO - Running: ['airflow', 'tasks', 'run', 'full_pipeline', 'flink_transform', 'scheduled__2025-04-17T13:00:00+00:00', '--job-id', '875', '--raw', '--subdir', 'DAGS_FOLDER/full_pipeline_dag.py', '--cfg-path', '/tmp/tmph8s0f8pt']
[2025-04-17T14:02:14.364+0000] {standard_task_runner.py:105} INFO - Job 875: Subtask flink_transform
[2025-04-17T14:02:14.505+0000] {task_command.py:467} INFO - Running <TaskInstance: full_pipeline.flink_transform scheduled__2025-04-17T13:00:00+00:00 [running]> on host 772d115850d3
[2025-04-17T14:02:14.670+0000] {taskinstance.py:3132} INFO - Exporting env vars: AIRFLOW_CTX_DAG_OWNER='data_team' AIRFLOW_CTX_DAG_ID='full_pipeline' AIRFLOW_CTX_TASK_ID='flink_transform' AIRFLOW_CTX_EXECUTION_DATE='2025-04-17T13:00:00+00:00' AIRFLOW_CTX_TRY_NUMBER='1' AIRFLOW_CTX_DAG_RUN_ID='scheduled__2025-04-17T13:00:00+00:00'
[2025-04-17T14:02:14.671+0000] {taskinstance.py:731} INFO - ::endgroup::
[2025-04-17T14:02:14.682+0000] {subprocess.py:78} INFO - Tmp dir root location: /tmp
[2025-04-17T14:02:14.685+0000] {subprocess.py:88} INFO - Running command: ['/usr/bin/bash', '-c', 'python /opt/airflow/pipeline/process/flink_stream.py']
[2025-04-17T14:02:14.696+0000] {subprocess.py:99} INFO - Output:
[2025-04-17T14:02:14.830+0000] {subprocess.py:106} INFO - Traceback (most recent call last):
[2025-04-17T14:02:14.830+0000] {subprocess.py:106} INFO -   File "/opt/airflow/pipeline/process/flink_stream.py", line 8, in <module>
[2025-04-17T14:02:14.833+0000] {subprocess.py:106} INFO -     import wget
[2025-04-17T14:02:14.834+0000] {subprocess.py:106} INFO - ModuleNotFoundError: No module named 'wget'
[2025-04-17T14:02:14.838+0000] {subprocess.py:110} INFO - Command exited with return code 1
[2025-04-17T14:02:14.986+0000] {taskinstance.py:3311} ERROR - Task failed with exception
Traceback (most recent call last):
  File "/home/airflow/.local/lib/python3.12/site-packages/airflow/models/taskinstance.py", line 767, in _execute_task
    result = _execute_callable(context=context, **execute_callable_kwargs)
             ^^^^^^^^^^^^^^^^^^^^^^^^^^^^^^^^^^^^^^^^^^^^^^^^^^^^^^^^^^^^^
  File "/home/airflow/.local/lib/python3.12/site-packages/airflow/models/taskinstance.py", line 733, in _execute_callable
    return ExecutionCallableRunner(
           ^^^^^^^^^^^^^^^^^^^^^^^^
  File "/home/airflow/.local/lib/python3.12/site-packages/airflow/utils/operator_helpers.py", line 252, in run
    return self.func(*args, **kwargs)
           ^^^^^^^^^^^^^^^^^^^^^^^^^^
  File "/home/airflow/.local/lib/python3.12/site-packages/airflow/models/baseoperator.py", line 422, in wrapper
    return func(self, *args, **kwargs)
           ^^^^^^^^^^^^^^^^^^^^^^^^^^^
  File "/home/airflow/.local/lib/python3.12/site-packages/airflow/operators/bash.py", line 276, in execute
    raise AirflowException(
airflow.exceptions.AirflowException: Bash command failed. The command returned a non-zero exit code 1.
[2025-04-17T14:02:14.996+0000] {taskinstance.py:1225} INFO - Marking task as UP_FOR_RETRY. dag_id=full_pipeline, task_id=flink_transform, run_id=scheduled__2025-04-17T13:00:00+00:00, execution_date=20250417T130000, start_date=20250417T140214, end_date=20250417T140214
[2025-04-17T14:02:15.020+0000] {taskinstance.py:340} INFO - ::group::Post task execution logs
[2025-04-17T14:02:15.021+0000] {standard_task_runner.py:124} ERROR - Failed to execute job 875 for task flink_transform (Bash command failed. The command returned a non-zero exit code 1.; 6194)
Traceback (most recent call last):
  File "/home/airflow/.local/lib/python3.12/site-packages/airflow/task/task_runner/standard_task_runner.py", line 117, in _start_by_fork
    ret = args.func(args, dag=self.dag)
          ^^^^^^^^^^^^^^^^^^^^^^^^^^^^^
  File "/home/airflow/.local/lib/python3.12/site-packages/airflow/cli/cli_config.py", line 49, in command
    return func(*args, **kwargs)
           ^^^^^^^^^^^^^^^^^^^^^
  File "/home/airflow/.local/lib/python3.12/site-packages/airflow/utils/cli.py", line 116, in wrapper
    return f(*args, **kwargs)
           ^^^^^^^^^^^^^^^^^^
  File "/home/airflow/.local/lib/python3.12/site-packages/airflow/cli/commands/task_command.py", line 483, in task_run
    task_return_code = _run_task_by_selected_method(args, _dag, ti)
                       ^^^^^^^^^^^^^^^^^^^^^^^^^^^^^^^^^^^^^^^^^^^^
  File "/home/airflow/.local/lib/python3.12/site-packages/airflow/cli/commands/task_command.py", line 256, in _run_task_by_selected_method
    return _run_raw_task(args, ti)
           ^^^^^^^^^^^^^^^^^^^^^^^
  File "/home/airflow/.local/lib/python3.12/site-packages/airflow/cli/commands/task_command.py", line 341, in _run_raw_task
    return ti._run_raw_task(
           ^^^^^^^^^^^^^^^^^
  File "/home/airflow/.local/lib/python3.12/site-packages/airflow/utils/session.py", line 97, in wrapper
    return func(*args, session=session, **kwargs)
           ^^^^^^^^^^^^^^^^^^^^^^^^^^^^^^^^^^^^^^
  File "/home/airflow/.local/lib/python3.12/site-packages/airflow/models/taskinstance.py", line 3005, in _run_raw_task
    return _run_raw_task(
           ^^^^^^^^^^^^^^
  File "/home/airflow/.local/lib/python3.12/site-packages/airflow/models/taskinstance.py", line 273, in _run_raw_task
    TaskInstance._execute_task_with_callbacks(
  File "/home/airflow/.local/lib/python3.12/site-packages/airflow/models/taskinstance.py", line 3159, in _execute_task_with_callbacks
    result = self._execute_task(context, task_orig)
             ^^^^^^^^^^^^^^^^^^^^^^^^^^^^^^^^^^^^^^
  File "/home/airflow/.local/lib/python3.12/site-packages/airflow/models/taskinstance.py", line 3183, in _execute_task
    return _execute_task(self, context, task_orig)
           ^^^^^^^^^^^^^^^^^^^^^^^^^^^^^^^^^^^^^^^
  File "/home/airflow/.local/lib/python3.12/site-packages/airflow/models/taskinstance.py", line 767, in _execute_task
    result = _execute_callable(context=context, **execute_callable_kwargs)
             ^^^^^^^^^^^^^^^^^^^^^^^^^^^^^^^^^^^^^^^^^^^^^^^^^^^^^^^^^^^^^
  File "/home/airflow/.local/lib/python3.12/site-packages/airflow/models/taskinstance.py", line 733, in _execute_callable
    return ExecutionCallableRunner(
           ^^^^^^^^^^^^^^^^^^^^^^^^
  File "/home/airflow/.local/lib/python3.12/site-packages/airflow/utils/operator_helpers.py", line 252, in run
    return self.func(*args, **kwargs)
           ^^^^^^^^^^^^^^^^^^^^^^^^^^
  File "/home/airflow/.local/lib/python3.12/site-packages/airflow/models/baseoperator.py", line 422, in wrapper
    return func(self, *args, **kwargs)
           ^^^^^^^^^^^^^^^^^^^^^^^^^^^
  File "/home/airflow/.local/lib/python3.12/site-packages/airflow/operators/bash.py", line 276, in execute
    raise AirflowException(
airflow.exceptions.AirflowException: Bash command failed. The command returned a non-zero exit code 1.
[2025-04-17T14:02:15.061+0000] {local_task_job_runner.py:266} INFO - Task exited with return code 1
[2025-04-17T14:02:15.112+0000] {taskinstance.py:3895} INFO - 0 downstream tasks scheduled from follow-on schedule check
[2025-04-17T14:02:15.114+0000] {local_task_job_runner.py:245} INFO - ::endgroup::
