[2025-03-30T23:03:24.309+0000] {local_task_job_runner.py:123} INFO - ::group::Pre task execution logs
[2025-03-30T23:03:24.361+0000] {taskinstance.py:2613} INFO - Dependencies all met for dep_context=non-requeueable deps ti=<TaskInstance: paris_air_quality_prod.daily_forecast manual__2025-03-30T23:03:14.227213+00:00 [queued]>
[2025-03-30T23:03:24.374+0000] {taskinstance.py:2613} INFO - Dependencies all met for dep_context=requeueable deps ti=<TaskInstance: paris_air_quality_prod.daily_forecast manual__2025-03-30T23:03:14.227213+00:00 [queued]>
[2025-03-30T23:03:24.374+0000] {taskinstance.py:2866} INFO - Starting attempt 1 of 3
[2025-03-30T23:03:24.391+0000] {taskinstance.py:2889} INFO - Executing <Task(PythonOperator): daily_forecast> on 2025-03-30 23:03:14.227213+00:00
[2025-03-30T23:03:24.403+0000] {standard_task_runner.py:104} INFO - Running: ['airflow', 'tasks', 'run', 'paris_air_quality_prod', 'daily_forecast', 'manual__2025-03-30T23:03:14.227213+00:00', '--job-id', '666', '--raw', '--subdir', 'DAGS_FOLDER/data_enriched_predict.py', '--cfg-path', '/tmp/tmpuyzx_fvu']
[2025-03-30T23:03:24.407+0000] {standard_task_runner.py:105} INFO - Job 666: Subtask daily_forecast
[2025-03-30T23:03:24.408+0000] {logging_mixin.py:190} WARNING - /home/airflow/.local/lib/python3.12/site-packages/airflow/task/task_runner/standard_task_runner.py:70 DeprecationWarning: This process (pid=4084) is multi-threaded, use of fork() may lead to deadlocks in the child.
[2025-03-30T23:03:24.409+0000] {standard_task_runner.py:72} INFO - Started process 4109 to run task
[2025-03-30T23:03:24.660+0000] {task_command.py:467} INFO - Running <TaskInstance: paris_air_quality_prod.daily_forecast manual__2025-03-30T23:03:14.227213+00:00 [running]> on host 04906466de51
[2025-03-30T23:03:24.832+0000] {taskinstance.py:3132} INFO - Exporting env vars: AIRFLOW_CTX_DAG_OWNER='airflow' AIRFLOW_CTX_DAG_ID='paris_air_quality_prod' AIRFLOW_CTX_TASK_ID='daily_forecast' AIRFLOW_CTX_EXECUTION_DATE='2025-03-30T23:03:14.227213+00:00' AIRFLOW_CTX_TRY_NUMBER='1' AIRFLOW_CTX_DAG_RUN_ID='manual__2025-03-30T23:03:14.227213+00:00'
[2025-03-30T23:03:24.834+0000] {taskinstance.py:731} INFO - ::endgroup::
[2025-03-30T23:03:24.847+0000] {data_enriched_predict.py:213} INFO - Début du workflow de prévision
[2025-03-30T23:03:24.895+0000] {base.py:84} INFO - Retrieving connection 'postgres_data'
[2025-03-30T23:03:24.897+0000] {data_enriched_predict.py:222} INFO - Exécution de la requête: SELECT * FROM data_warehouse WHERE city = 'Paris'
[2025-03-30T23:03:24.960+0000] {data_enriched_predict.py:224} INFO - Données chargées de la base: 160 lignes
[2025-03-30T23:03:24.960+0000] {data_enriched_predict.py:225} INFO - Colonnes de la base: ['city', 'timestamp', 'aqi', 'pm25', 'pm10', 'temperature', 'humidity', 'pressure']
[2025-03-30T23:03:26.173+0000] {base.py:84} INFO - Retrieving connection 'postgres_data'
[2025-03-30T23:03:26.220+0000] {data_enriched_predict.py:117} ERROR - Erreur API AirVisual: 'Connection' object has no attribute 'commit'
Traceback (most recent call last):
  File "/opt/airflow/dags/data_enriched_predict.py", line 108, in safe_fetch_airvisual
    conn.commit()
    ^^^^^^^^^^^
AttributeError: 'Connection' object has no attribute 'commit'
[2025-03-30T23:03:26.227+0000] {data_enriched_predict.py:178} INFO - Données initiales: 160 lignes
[2025-03-30T23:03:26.228+0000] {data_enriched_predict.py:179} INFO - Colonnes disponibles: ['city', 'timestamp', 'aqi', 'pm25', 'pm10', 'temperature', 'humidity', 'pressure']
[2025-03-30T23:03:26.232+0000] {data_enriched_predict.py:190} INFO - Données avant dropna: 160 lignes
[2025-03-30T23:03:26.232+0000] {data_enriched_predict.py:191} INFO - Colonnes après feature engineering: ['city', 'timestamp', 'aqi', 'pm25', 'pm10', 'temperature', 'humidity', 'pressure', 'hour', 'day_of_week', 'month']
[2025-03-30T23:03:26.235+0000] {data_enriched_predict.py:195} INFO - Données après dropna: 160 lignes
[2025-03-30T23:03:26.237+0000] {data_enriched_predict.py:203} INFO - Nombre de valeurs NaN par colonne:
city           0
timestamp      0
aqi            0
pm25           0
pm10           0
temperature    0
humidity       0
pressure       0
hour           0
day_of_week    0
month          0
dtype: int64
[2025-03-30T23:03:26.238+0000] {data_enriched_predict.py:261} INFO - Features utilisées pour l'entraînement: ['hour', 'day_of_week', 'month', 'temperature', 'humidity', 'pressure']
[2025-03-30T23:03:26.284+0000] {data_enriched_predict.py:268} INFO - Validation Fold 1 - R²: 1.00
[2025-03-30T23:03:26.309+0000] {data_enriched_predict.py:268} INFO - Validation Fold 2 - R²: 1.00
[2025-03-30T23:03:26.309+0000] {data_enriched_predict.py:132} INFO - Récupération des données OpenMeteo avec les paramètres: {'latitude': 48.8566, 'longitude': 2.3522, 'hourly': 'temperature_2m,relative_humidity_2m,pressure_msl,precipitation', 'forecast_days': 16, 'timezone': 'Europe/Paris', 'models': 'ecmwf_ifs04'}
[2025-03-30T23:03:26.495+0000] {base.py:84} INFO - Retrieving connection 'postgres_data'
[2025-03-30T23:03:26.665+0000] {data_enriched_predict.py:167} ERROR - Erreur OpenMeteo: 'Connection' object has no attribute 'commit'
Traceback (most recent call last):
  File "/opt/airflow/dags/data_enriched_predict.py", line 155, in get_openmeteo_forecast
    conn.commit()
    ^^^^^^^^^^^
AttributeError: 'Connection' object has no attribute 'commit'
[2025-03-30T23:03:26.668+0000] {data_enriched_predict.py:335} ERROR - Échec du workflow: Aucune donnée météo récupérée
Traceback (most recent call last):
  File "/opt/airflow/dags/data_enriched_predict.py", line 277, in train_and_forecast
    raise ValueError("Aucune donnée météo récupérée")
ValueError: Aucune donnée météo récupérée
[2025-03-30T23:03:26.671+0000] {taskinstance.py:3311} ERROR - Task failed with exception
Traceback (most recent call last):
  File "/home/airflow/.local/lib/python3.12/site-packages/airflow/models/taskinstance.py", line 767, in _execute_task
    result = _execute_callable(context=context, **execute_callable_kwargs)
             ^^^^^^^^^^^^^^^^^^^^^^^^^^^^^^^^^^^^^^^^^^^^^^^^^^^^^^^^^^^^^
  File "/home/airflow/.local/lib/python3.12/site-packages/airflow/models/taskinstance.py", line 733, in _execute_callable
    return ExecutionCallableRunner(
           ^^^^^^^^^^^^^^^^^^^^^^^^
  File "/home/airflow/.local/lib/python3.12/site-packages/airflow/utils/operator_helpers.py", line 252, in run
    return self.func(*args, **kwargs)
           ^^^^^^^^^^^^^^^^^^^^^^^^^^
  File "/home/airflow/.local/lib/python3.12/site-packages/airflow/models/baseoperator.py", line 422, in wrapper
    return func(self, *args, **kwargs)
           ^^^^^^^^^^^^^^^^^^^^^^^^^^^
  File "/home/airflow/.local/lib/python3.12/site-packages/airflow/operators/python.py", line 238, in execute
    return_value = self.execute_callable()
                   ^^^^^^^^^^^^^^^^^^^^^^^
  File "/home/airflow/.local/lib/python3.12/site-packages/airflow/operators/python.py", line 256, in execute_callable
    return runner.run(*self.op_args, **self.op_kwargs)
           ^^^^^^^^^^^^^^^^^^^^^^^^^^^^^^^^^^^^^^^^^^^
  File "/home/airflow/.local/lib/python3.12/site-packages/airflow/utils/operator_helpers.py", line 252, in run
    return self.func(*args, **kwargs)
           ^^^^^^^^^^^^^^^^^^^^^^^^^^
  File "/opt/airflow/dags/data_enriched_predict.py", line 277, in train_and_forecast
    raise ValueError("Aucune donnée météo récupérée")
ValueError: Aucune donnée météo récupérée
[2025-03-30T23:03:26.831+0000] {taskinstance.py:1225} INFO - Marking task as UP_FOR_RETRY. dag_id=paris_air_quality_prod, task_id=daily_forecast, run_id=manual__2025-03-30T23:03:14.227213+00:00, execution_date=20250330T230314, start_date=20250330T230324, end_date=20250330T230326
[2025-03-30T23:03:26.861+0000] {taskinstance.py:340} INFO - ::group::Post task execution logs
[2025-03-30T23:03:26.862+0000] {standard_task_runner.py:124} ERROR - Failed to execute job 666 for task daily_forecast (Aucune donnée météo récupérée; 4109)
Traceback (most recent call last):
  File "/home/airflow/.local/lib/python3.12/site-packages/airflow/task/task_runner/standard_task_runner.py", line 117, in _start_by_fork
    ret = args.func(args, dag=self.dag)
          ^^^^^^^^^^^^^^^^^^^^^^^^^^^^^
  File "/home/airflow/.local/lib/python3.12/site-packages/airflow/cli/cli_config.py", line 49, in command
    return func(*args, **kwargs)
           ^^^^^^^^^^^^^^^^^^^^^
  File "/home/airflow/.local/lib/python3.12/site-packages/airflow/utils/cli.py", line 116, in wrapper
    return f(*args, **kwargs)
           ^^^^^^^^^^^^^^^^^^
  File "/home/airflow/.local/lib/python3.12/site-packages/airflow/cli/commands/task_command.py", line 483, in task_run
    task_return_code = _run_task_by_selected_method(args, _dag, ti)
                       ^^^^^^^^^^^^^^^^^^^^^^^^^^^^^^^^^^^^^^^^^^^^
  File "/home/airflow/.local/lib/python3.12/site-packages/airflow/cli/commands/task_command.py", line 256, in _run_task_by_selected_method
    return _run_raw_task(args, ti)
           ^^^^^^^^^^^^^^^^^^^^^^^
  File "/home/airflow/.local/lib/python3.12/site-packages/airflow/cli/commands/task_command.py", line 341, in _run_raw_task
    return ti._run_raw_task(
           ^^^^^^^^^^^^^^^^^
  File "/home/airflow/.local/lib/python3.12/site-packages/airflow/utils/session.py", line 97, in wrapper
    return func(*args, session=session, **kwargs)
           ^^^^^^^^^^^^^^^^^^^^^^^^^^^^^^^^^^^^^^
  File "/home/airflow/.local/lib/python3.12/site-packages/airflow/models/taskinstance.py", line 3005, in _run_raw_task
    return _run_raw_task(
           ^^^^^^^^^^^^^^
  File "/home/airflow/.local/lib/python3.12/site-packages/airflow/models/taskinstance.py", line 273, in _run_raw_task
    TaskInstance._execute_task_with_callbacks(
  File "/home/airflow/.local/lib/python3.12/site-packages/airflow/models/taskinstance.py", line 3159, in _execute_task_with_callbacks
    result = self._execute_task(context, task_orig)
             ^^^^^^^^^^^^^^^^^^^^^^^^^^^^^^^^^^^^^^
  File "/home/airflow/.local/lib/python3.12/site-packages/airflow/models/taskinstance.py", line 3183, in _execute_task
    return _execute_task(self, context, task_orig)
           ^^^^^^^^^^^^^^^^^^^^^^^^^^^^^^^^^^^^^^^
  File "/home/airflow/.local/lib/python3.12/site-packages/airflow/models/taskinstance.py", line 767, in _execute_task
    result = _execute_callable(context=context, **execute_callable_kwargs)
             ^^^^^^^^^^^^^^^^^^^^^^^^^^^^^^^^^^^^^^^^^^^^^^^^^^^^^^^^^^^^^
  File "/home/airflow/.local/lib/python3.12/site-packages/airflow/models/taskinstance.py", line 733, in _execute_callable
    return ExecutionCallableRunner(
           ^^^^^^^^^^^^^^^^^^^^^^^^
  File "/home/airflow/.local/lib/python3.12/site-packages/airflow/utils/operator_helpers.py", line 252, in run
    return self.func(*args, **kwargs)
           ^^^^^^^^^^^^^^^^^^^^^^^^^^
  File "/home/airflow/.local/lib/python3.12/site-packages/airflow/models/baseoperator.py", line 422, in wrapper
    return func(self, *args, **kwargs)
           ^^^^^^^^^^^^^^^^^^^^^^^^^^^
  File "/home/airflow/.local/lib/python3.12/site-packages/airflow/operators/python.py", line 238, in execute
    return_value = self.execute_callable()
                   ^^^^^^^^^^^^^^^^^^^^^^^
  File "/home/airflow/.local/lib/python3.12/site-packages/airflow/operators/python.py", line 256, in execute_callable
    return runner.run(*self.op_args, **self.op_kwargs)
           ^^^^^^^^^^^^^^^^^^^^^^^^^^^^^^^^^^^^^^^^^^^
  File "/home/airflow/.local/lib/python3.12/site-packages/airflow/utils/operator_helpers.py", line 252, in run
    return self.func(*args, **kwargs)
           ^^^^^^^^^^^^^^^^^^^^^^^^^^
  File "/opt/airflow/dags/data_enriched_predict.py", line 277, in train_and_forecast
    raise ValueError("Aucune donnée météo récupérée")
ValueError: Aucune donnée météo récupérée
[2025-03-30T23:03:26.878+0000] {local_task_job_runner.py:266} INFO - Task exited with return code 1
[2025-03-30T23:03:26.938+0000] {taskinstance.py:3895} INFO - 0 downstream tasks scheduled from follow-on schedule check
[2025-03-30T23:03:26.941+0000] {local_task_job_runner.py:245} INFO - ::endgroup::
